2023-12-18 14:20:24,480 - INSERT_Error - ERROR - There was an error in the INSERT query
Traceback (most recent call last):
  File "C:\Users\diego.nunez\Documents\CodeSource\Python\WIP_Report\src\loading.py", line 163, in load_wip_data
    cursor.execute(insert_query_main)
pyodbc.Error: ('21S01', '[21S01] [Microsoft][ODBC SQL Server Driver][SQL Server]Column name or number of supplied values does not match table definition. (213) (SQLExecDirectW)')
2023-12-20 09:47:18,166 - INSERT_Error - ERROR - There was an error in the INSERT query
Traceback (most recent call last):
  File "C:\Users\diego.nunez\Documents\CodeSource\Python\WIP_report\src\loading.py", line 147, in load_wip_data
    cursor.execute(insert_query_temp.format(pro_num,
pyodbc.DataError: ('22007', '[22007] [Microsoft][ODBC SQL Server Driver][SQL Server]Conversion failed when converting date and/or time from character string. (241) (SQLExecDirectW)')
2023-12-20 09:47:19,729 - INSERT_Error - ERROR - There was an error in the INSERT query
Traceback (most recent call last):
  File "C:\Users\diego.nunez\Documents\CodeSource\Python\WIP_report\src\loading.py", line 147, in load_wip_data
    cursor.execute(insert_query_temp.format(pro_num,
pyodbc.DataError: ('22007', '[22007] [Microsoft][ODBC SQL Server Driver][SQL Server]Conversion failed when converting date and/or time from character string. (241) (SQLExecDirectW)')
2023-12-20 09:47:21,211 - INSERT_Error - ERROR - There was an error in the INSERT query
Traceback (most recent call last):
  File "C:\Users\diego.nunez\Documents\CodeSource\Python\WIP_report\src\loading.py", line 129, in load_wip_data
    cursor.execute(insert_query_temp.format(pro_num,
pyodbc.DataError: ('22007', '[22007] [Microsoft][ODBC SQL Server Driver][SQL Server]Conversion failed when converting date and/or time from character string. (241) (SQLExecDirectW)')
2023-12-20 14:47:06,248 - RunTime_Error - ERROR - An error occurred and the operation did not complete. Please check log.
Traceback (most recent call last):
  File "C:\Users\diego.nunez\AppData\Local\Programs\Python\Python310\lib\multiprocessing\managers.py", line 810, in _callmethod
    conn = self._tls.connection
AttributeError: 'ForkAwareLocal' object has no attribute 'connection'

During handling of the above exception, another exception occurred:

Traceback (most recent call last):
  File "C:\Users\diego.nunez\Documents\CodeSource\Python\WIP_report\src\main.py", line 150, in <module>
    update_shipmentFlag(conn_sbi, unpacked_SNs)
  File "C:\Users\diego.nunez\Documents\CodeSource\Python\WIP_Report\src\update.py", line 40, in update_shipmentFlag
    {items_to_SQL_values(collection=wip_unpacked)}
  File "C:\Users\diego.nunez\Documents\CodeSource\Python\WIP_Report\src\utilities.py", line 189, in items_to_SQL_values
    sql_values = ["(" + "'" + item + "'" + ")" + "," for item in collection]
  File "C:\Users\diego.nunez\Documents\CodeSource\Python\WIP_Report\src\utilities.py", line 189, in <listcomp>
    sql_values = ["(" + "'" + item + "'" + ")" + "," for item in collection]
  File "<string>", line 2, in __getitem__
  File "C:\Users\diego.nunez\AppData\Local\Programs\Python\Python310\lib\multiprocessing\managers.py", line 814, in _callmethod
    self._connect()
  File "C:\Users\diego.nunez\AppData\Local\Programs\Python\Python310\lib\multiprocessing\managers.py", line 801, in _connect
    conn = self._Client(self._token.address, authkey=self._authkey)
  File "C:\Users\diego.nunez\AppData\Local\Programs\Python\Python310\lib\multiprocessing\connection.py", line 505, in Client
    c = PipeClient(address)
  File "C:\Users\diego.nunez\AppData\Local\Programs\Python\Python310\lib\multiprocessing\connection.py", line 707, in PipeClient
    _winapi.WaitNamedPipe(address, 1000)
FileNotFoundError: [WinError 2] The system cannot find the file specified
